Workbook
Name Portfolio_Sharpe: 'Portfolio '!$B$26
Name Portfolio_Sharpe: #REF!
Name Risk_Free_rate: Risk_Analysis!$B$13

Sheet Raw_Data
A1: GLD
A2: Date | B2: Price | C2: Open | D2: High | E2: Low | F2: Vol. | G2: Change %
A3: 46023 | B3: 421.29 | C3: 401.8 | D3: 426.84 | E3: 396.31 | F3: 156.48M | G3: 0.063
A4: 45669 | B4: 396.31 | C4: 390.61 | D4: 418.45 | E4: 382.91 | F4: 232.08M | G4: 0.0217
A5: 45668 | B5: 387.88 | C5: 368.91 | D5: 388.18 | E5: 361.39 | F5: 209.29M | G5: 0.0537
A6: 45667 | B6: 368.12 | C6: 356.17 | D6: 403.3 | E6: 351.4 | F6: 553.02M | G6: 0.0356
A7: 45666 | B7: 355.47 | C7: 320.82 | D7: 355.57 | E7: 320.24 | F7: 302.00M | G7: 0.1176
A8: 45665 | B8: 318.07 | C8: 308.61 | D8: 318.09 | E8: 305.19 | F8: 178.58M | G8: 0.0499
A9: 45664 | B9: 302.96 | C9: 308.55 | D9: 316.24 | E9: 300.95 | F9: 202.61M | G9: -0.0061
A10: 45663 | B10: 304.83 | C10: 309.21 | D10: 317.6 | E10: 299.89 | F10: 199.60M | G10: 0.0041
A11: 45662 | B11: 303.6 | C11: 297.41 | D11: 315.62 | E11: 291.78 | F11: 235.25M | G11: -0.0006
A12: 45661 | B12: 303.77 | C12: 288.54 | D12: 317.63 | E12: 272.58 | F12: 354.30M | G12: 0.0542
A13: 45660 | B13: 288.14 | C13: 265.07 | D13: 288.39 | E13: 265.07 | F13: 181.03M | G13: 0.0945
A14: 45659 | B14: 263.27 | C14: 259.75 | D14: 272.32 | E14: 259.52 | F14: 178.99M | G14: 0.0182
... A135: 42005 | B135: 123.45 | C135: 112.49 | D135: 125.58 | E135: 112.32 | F135: 198.03M | G135: 0.0869
A137: XOM
A138: Date | B138: Price | C138: Open | D138: High | E138: Low | F138: Vol. | G138: Change %
A139: 46023 | B139: 129.89 | C139: 120.05 | D139: 131.72 | E139: 118.27 | F139: 191.96M | G139: 0.0794
A140: 45669 | B140: 120.34 | C140: 116.1 | D140: 121.8 | E140: 114.61 | F140: 344.72M | G140: 0.0381
A141: 45668 | B141: 115.92 | C141: 114.5 | D141: 120.81 | E141: 112.51 | F141: 279.42M | G141: 0.0136
A142: 45667 | B142: 114.36 | C142: 112.56 | D142: 117.05 | E142: 110.39 | F142: 288.64M | G142: 0.0143
A143: 45666 | B143: 112.75 | C143: 114.18 | D143: 118.36 | E143: 108.35 | F143: 351.99M | G143: -0.0135
A144: 45665 | B144: 114.29 | C144: 112 | D144: 114.79 | E144: 105.53 | F144: 327.74M | G144: 0.0237
A145: 45664 | B145: 111.64 | C145: 108.13 | D145: 115.76 | E145: 107.15 | F145: 317.77M | G145: 0.0356
A146: 45663 | B146: 107.8 | C146: 103.75 | D146: 116.95 | E146: 101.73 | F146: 410.07M | G146: 0.0538
A147: 45662 | B147: 102.3 | C147: 105.1 | D147: 110.51 | E147: 101.18 | F147: 327.02M | G147: -0.0315
A148: 45661 | B148: 105.63 | C148: 119.22 | D148: 119.28 | E148: 97.8 | F148: 398.12M | G148: -0.1118
A149: 45660 | B149: 118.93 | C149: 111.7 | D149: 119.9 | E149: 103.67 | F149: 385.65M | G149: 0.0683
A150: 45659 | B150: 111.33 | C150: 106.64 | D150: 112.51 | E150: 105.32 | F150: 274.85M | G150: 0.0421
... A271: 42005 | B271: 87.42 | C271: 92.25 | D271: 93.05 | E271: 86.03 | F271: 326.82M | G271: -0.0544
A273: SPY
A274: Date | B274: Price | C274: Open | D274: High | E274: Low | F274: Vol. | G274: Change %
A275: 46023 | B275: 691.66 | C275: 685.64 | D275: 696.07 | E275: 679.87 | F275: 771.60M | G275: 0.0143
A276: 45669 | B276: 681.92 | C276: 678.81 | D276: 691.66 | E276: 671.2 | F276: 1.66B | G276: -0.0022
A277: 45668 | B277: 683.39 | C277: 685.67 | D277: 685.8 | E277: 650.85 | F277: 1.66B | G277: 0.002
A278: 45667 | B278: 682.06 | C278: 663.17 | D278: 689.7 | E278: 652.84 | F278: 1.78B | G278: 0.0238
A279: 45666 | B279: 666.18 | C279: 637.5 | D279: 667.34 | E279: 634.92 | F279: 1.61B | G279: 0.0328
A280: 45665 | B280: 645.05 | C280: 626.3 | D280: 649.48 | E280: 619.29 | F280: 1.42B | G280: 0.0205
A281: 45664 | B281: 632.08 | C281: 616.36 | D281: 639.85 | E281: 615.52 | F281: 1.48B | G281: 0.023
A282: 45663 | B282: 617.85 | C282: 587.76 | D282: 619.22 | E282: 585.06 | F282: 1.50B | G282: 0.0483
...

Sheet Clean_Data
A1: GLD
A2: Date | B2: Price
A3: 46023 | B3: 421.29
A4: 45992 | B4: 396.31
A5: 45962 | B5: 387.88
A6: 45931 | B6: 368.12
A7: 45901 | B7: 355.47
A8: 45870 | B8: 318.07
A9: 45839 | B9: 302.96
A10: 45809 | B10: 304.83
A11: 45778 | B11: 303.6
A12: 45748 | B12: 303.77
A13: 45717 | B13: 288.14
A14: 45689 | B14: 263.27
... A135: 42005 | B135: 123.45
A138: XOM
A139: Date | B139: Price
A140: 46023 | B140: 129.89
A141: 45992 | B141: 120.34 | D141: =MONTH(Table3[[#This Row],[Date]]) -> 12
A142: 45962 | B142: 115.92
A143: 45931 | B143: 114.36
A144: 45901 | B144: 112.75
A145: 45870 | B145: 114.29
A146: 45839 | B146: 111.64
A147: 45809 | B147: 107.8
A148: 45778 | B148: 102.3
A149: 45748 | B149: 105.63
A150: 45717 | B150: 118.93
A151: 45689 | B151: 111.33
A152: 45658 | B152: 106.83
A153: 45627 | B153: 107.57
... A272: 42005 | B272: 87.42
A275: SPY
A276: Date | B276: Price
A277: 46023 | B277: 691.66
A278: 45992 | B278: 681.92 | D278: =MONTH(Table4[[#This Row],[Date]]) -> 12
A279: 45962 | B279: 683.39
A280: 45931 | B280: 682.06
A281: 45901 | B281: 666.18
A282: 45870 | B282: 645.05
...

Sheet Assumptions
B3: Parameter | C3: Value
B4: Risk-Free Rate (Annual) | C4: 0.04
B5: Risk-Free Rate (Monthly) | C5: =(1+C4)^(1/12)-1 -> 0.0032737398
B6: Return Frequency | C6: Monthly
B7: Return Type | C7: Simple
B8: Benchmark (Market) | C8: SPY
B9: Sample Start | C9: 42005
B10: Sample End | C10: 46023
B11: VaR Method | C11: Historical
B12: VaR Confidence Levels | C12: 90%, 95%, 99%

Sheet TimeLine
A1: Date | B1: GLD | C1: XOM | D1: SPY | E1: JPM | F1: NVDA | G1: PG | H1: TLT | I1: VGT | J1: VNQ | K1: VXUS
A2: 42005 | B2: =INDEX(Table2[Price],MATCH(TimeLine!A2,Table2[Date],0)) -> 123.45 | C2: =INDEX(Table3[Price],MATCH(TimeLine!A2,Table3[Date],0)) -> 87.42 | D2: =INDEX(Table4[Price],MATCH(TimeLine!A2,Table4[Date],0)) -> 199.45 | E2: =INDEX(Table5[Price],MATCH(TimeLine!A2,Table5[Date],0)) -> 54.38 | F2: =INDEX(Table6[Price],MATCH(TimeLine!A2,Table6[Date],0)) -> 0.48 | G2: =INDEX(PG[PG],MATCH(Table_RawData[[#This Row],[Date]],PG[Date],0)) -> 84.29 | H2: =INDEX(TLT[TLT],MATCH(Table_RawData[[#This Row],[Date]],TLT[Date],0)) -> 138.28 | I2: =INDEX(VGT[VGT],MATCH(Table_RawData[[#This Row],[Date]],VGT[Date],0)) -> 100.81 | J2: =INDEX(VNQ[VNQ],MATCH(Table_RawData[[#This Row],[Date]],VNQ[Date],0)) -> 86.55 | K2: =INDEX(VXUS[VXUS],MATCH(Table_RawData[[#This Row],[Date]],VXUS[Date],0)) -> 48.47
A3: =EDATE(A2,1) -> 42036 | B3: =INDEX(Table2[Price],MATCH(TimeLine!A3,Table2[Date],0)) -> 116.16 | C3: =INDEX(Table3[Price],MATCH(TimeLine!A3,Table3[Date],0)) -> 88.54 | D3: =INDEX(Table4[Price],MATCH(TimeLine!A3,Table4[Date],0)) -> 210.66 | E3: =INDEX(Table5[Price],MATCH(TimeLine!A3,Table5[Date],0)) -> 61.28 | F3: =INDEX(Table6[Price],MATCH(TimeLine!A3,Table6[Date],0)) -> 0.55 | G3: =INDEX(PG[PG],MATCH(Table_RawData[[#This Row],[Date]],PG[Date],0)) -> 85.13 | H3: =INDEX(TLT[TLT],MATCH(Table_RawData[[#This Row],[Date]],TLT[Date],0)) -> 129.53 | I3: =INDEX(VGT[VGT],MATCH(Table_RawData[[#This Row],[Date]],VGT[Date],0)) -> 109.21 | J3: =INDEX(VNQ[VNQ],MATCH(Table_RawData[[#This Row],[Date]],VNQ[Date],0)) -> 83.37 | K3: =INDEX(VXUS[VXUS],MATCH(Table_RawData[[#This Row],[Date]],VXUS[Date],0)) -> 51.27
A4: =EDATE(A3,1) -> 42064 | B4: =INDEX(Table2[Price],MATCH(TimeLine!A4,Table2[Date],0)) -> 113.66 | C4: =INDEX(Table3[Price],MATCH(TimeLine!A4,Table3[Date],0)) -> 85 | D4: =INDEX(Table4[Price],MATCH(TimeLine!A4,Table4[Date],0)) -> 206.43 | E4: =INDEX(Table5[Price],MATCH(TimeLine!A4,Table5[Date],0)) -> 60.58 | F4: =INDEX(Table6[Price],MATCH(TimeLine!A4,Table6[Date],0)) -> 0.52 | G4: =INDEX(PG[PG],MATCH(Table_RawData[[#This Row],[Date]],PG[Date],0)) -> 81.94 | H4: =INDEX(TLT[TLT],MATCH(Table_RawData[[#This Row],[Date]],TLT[Date],0)) -> 130.69 | I4: =INDEX(VGT[VGT],MATCH(Table_RawData[[#This Row],[Date]],VGT[Date],0)) -> 106.52 | J4: =INDEX(VNQ[VNQ],MATCH(Table_RawData[[#This Row],[Date]],VNQ[Date],0)) -> 84.31 | K4: =INDEX(VXUS[VXUS],MATCH(Table_RawData[[#This Row],[Date]],VXUS[Date],0)) -> 50.35
A5: =EDATE(A4,1) -> 42095 | B5: =INDEX(Table2[Price],MATCH(TimeLine!A5,Table2[Date],0)) -> 113.47 | C5: =INDEX(Table3[Price],MATCH(TimeLine!A5,Table3[Date],0)) -> 87.37 | D5: =INDEX(Table4[Price],MATCH(TimeLine!A5,Table4[Date],0)) -> 208.46 | E5: =INDEX(Table5[Price],MATCH(TimeLine!A5,Table5[Date],0)) -> 63.26 | F5: =INDEX(Table6[Price],MATCH(TimeLine!A5,Table6[Date],0)) -> 0.55 | G5: =INDEX(PG[PG],MATCH(Table_RawData[[#This Row],[Date]],PG[Date],0)) -> 79.51 | H5: =INDEX(TLT[TLT],MATCH(Table_RawData[[#This Row],[Date]],TLT[Date],0)) -> 125.95 | I5: =INDEX(VGT[VGT],MATCH(Table_RawData[[#This Row],[Date]],VGT[Date],0)) -> 107.89 | J5: =INDEX(VNQ[VNQ],MATCH(Table_RawData[[#This Row],[Date]],VNQ[Date],0)) -> 79.38 | K5: =INDEX(VXUS[VXUS],MATCH(Table_RawData[[#This Row],[Date]],VXUS[Date],0)) -> 52.77
A6: =EDATE(A5,1) -> 42125 | B6: =INDEX(Table2[Price],MATCH(TimeLine!A6,Table2[Date],0)) -> 114.1 | C6: =INDEX(Table3[Price],MATCH(TimeLine!A6,Table3[Date],0)) -> 85.2 | D6: =INDEX(Table4[Price],MATCH(TimeLine!A6,Table4[Date],0)) -> 211.14 | E6: =INDEX(Table5[Price],MATCH(TimeLine!A6,Table5[Date],0)) -> 65.78 | F6: =INDEX(Table6[Price],MATCH(TimeLine!A6,Table6[Date],0)) -> 0.55 | G6: =INDEX(PG[PG],MATCH(Table_RawData[[#This Row],[Date]],PG[Date],0)) -> 78.39 | H6: =INDEX(TLT[TLT],MATCH(Table_RawData[[#This Row],[Date]],TLT[Date],0)) -> 122.71 | I6: =INDEX(VGT[VGT],MATCH(Table_RawData[[#This Row],[Date]],VGT[Date],0)) -> 110.58 | J6: =INDEX(VNQ[VNQ],MATCH(Table_RawData[[#This Row],[Date]],VNQ[Date],0)) -> 79.14 | K6: =INDEX(VXUS[VXUS],MATCH(Table_RawData[[#This Row],[Date]],VXUS[Date],0)) -> 52.29
A7: =EDATE(A6,1) -> 42156 | B7: =INDEX(Table2[Price],MATCH(TimeLine!A7,Table2[Date],0)) -> 112.37 | C7: =INDEX(Table3[Price],MATCH(TimeLine!A7,Table3[Date],0)) -> 83.2 | D7: =INDEX(Table4[Price],MATCH(TimeLine!A7,Table4[Date],0)) -> 205.85 | E7: =INDEX(Table5[Price],MATCH(TimeLine!A7,Table5[Date],0)) -> 67.76 | F7: =INDEX(Table6[Price],MATCH(TimeLine!A7,Table6[Date],0)) -> 0.5 | G7: =INDEX(PG[PG],MATCH(Table_RawData[[#This Row],[Date]],PG[Date],0)) -> 78.24 | H7: =INDEX(TLT[TLT],MATCH(Table_RawData[[#This Row],[Date]],TLT[Date],0)) -> 117.46 | I7: =INDEX(VGT[VGT],MATCH(Table_RawData[[#This Row],[Date]],VGT[Date],0)) -> 106.23 | J7: =INDEX(VNQ[VNQ],MATCH(Table_RawData[[#This Row],[Date]],VNQ[Date],0)) -> 74.69 | K7: =INDEX(VXUS[VXUS],MATCH(Table_RawData[[#This Row],[Date]],VXUS[Date],0)) -> 50.33
A8: =EDATE(A7,1) -> 42186 | B8: =INDEX(Table2[Price],MATCH(TimeLine!A8,Table2[Date],0)) -> 104.93 | C8: =INDEX(Table3[Price],MATCH(TimeLine!A8,Table3[Date],0)) -> 79.21 | D8: =INDEX(Table4[Price],MATCH(TimeLine!A8,Table4[Date],0)) -> 210.5 | E8: =INDEX(Table5[Price],MATCH(TimeLine!A8,Table5[Date],0)) -> 68.53 | F8: =INDEX(Table6[Price],MATCH(TimeLine!A8,Table6[Date],0)) -> 0.5 | G8: =INDEX(PG[PG],MATCH(Table_RawData[[#This Row],[Date]],PG[Date],0)) -> 76.7 | H8: =INDEX(TLT[TLT],MATCH(Table_RawData[[#This Row],[Date]],TLT[Date],0)) -> 122.53 | I8: =INDEX(VGT[VGT],MATCH(Table_RawData[[#This Row],[Date]],VGT[Date],0)) -> 108.64 | J8: =INDEX(VNQ[VNQ],MATCH(Table_RawData[[#This Row],[Date]],VNQ[Date],0)) -> 79 | K8: =INDEX(VXUS[VXUS],MATCH(Table_RawData[[#This Row],[Date]],VXUS[Date],0)) -> 50.05
A9: =EDATE(A8,1) -> 42217 | B9: =INDEX(Table2[Price],MATCH(TimeLine!A9,Table2[Date],0)) -> 108.82 | C9: =INDEX(Table3[Price],MATCH(TimeLine!A9,Table3[Date],0)) -> 75.24 | D9: =INDEX(Table4[Price],MATCH(TimeLine!A9,Table4[Date],0)) -> 197.67 | E9: =INDEX(Table5[Price],MATCH(TimeLine!A9,Table5[Date],0)) -> 64.1 | F9: =INDEX(Table6[Price],MATCH(TimeLine!A9,Table6[Date],0)) -> 0.56 | G9: =INDEX(PG[PG],MATCH(Table_RawData[[#This Row],[Date]],PG[Date],0)) -> 70.67 | H9: =INDEX(TLT[TLT],MATCH(Table_RawData[[#This Row],[Date]],TLT[Date],0)) -> 121.42 | I9: =INDEX(VGT[VGT],MATCH(Table_RawData[[#This Row],[Date]],VGT[Date],0)) -> 102.34 | J9: =INDEX(VNQ[VNQ],MATCH(Table_RawData[[#This Row],[Date]],VNQ[Date],0)) -> 74.03 | K9: =INDEX(VXUS[VXUS],MATCH(Table_RawData[[#This Row],[Date]],VXUS[Date],0)) -> 46.33
A10: =EDATE(A9,1) -> 42248 | B10: =INDEX(Table2[Price],MATCH(TimeLine!A10,Table2[Date],0)) -> 106.86 | C10: =INDEX(Table3[Price],MATCH(TimeLine!A10,Table3[Date],0)) -> 74.35 | D10: =INDEX(Table4[Price],MATCH(TimeLine!A10,Table4[Date],0)) -> 191.63 | E10: =INDEX(Table5[Price],MATCH(TimeLine!A10,Table5[Date],0)) -> 60.97 | F10: =INDEX(Table6[Price],MATCH(TimeLine!A10,Table6[Date],0)) -> 0.62 | G10: =INDEX(PG[PG],MATCH(Table_RawData[[#This Row],[Date]],PG[Date],0)) -> 71.94 | H10: =INDEX(TLT[TLT],MATCH(Table_RawData[[#This Row],[Date]],TLT[Date],0)) -> 123.54 | I10: =INDEX(VGT[VGT],MATCH(Table_RawData[[#This Row],[Date]],VGT[Date],0)) -> 100 | J10: =INDEX(VNQ[VNQ],MATCH(Table_RawData[[#This Row],[Date]],VNQ[Date],0)) -> 75.54 | K10: =INDEX(VXUS[VXUS],MATCH(Table_RawData[[#This Row],[Date]],VXUS[Date],0)) -> 44.32
A11: =EDATE(A10,1) -> 42278 | B11: =INDEX(Table2[Price],MATCH(TimeLine!A11,Table2[Date],0)) -> 109.3 | C11: =INDEX(Table3[Price],MATCH(TimeLine!A11,Table3[Date],0)) -> 82.74 | D11: =INDEX(Table4[Price],MATCH(TimeLine!A11,Table4[Date],0)) -> 207.93 | E11: =INDEX(Table5[Price],MATCH(TimeLine!A11,Table5[Date],0)) -> 64.25 | F11: =INDEX(Table6[Price],MATCH(TimeLine!A11,Table6[Date],0)) -> 0.71 | G11: =INDEX(PG[PG],MATCH(Table_RawData[[#This Row],[Date]],PG[Date],0)) -> 76.38 | H11: =INDEX(TLT[TLT],MATCH(Table_RawData[[#This Row],[Date]],TLT[Date],0)) -> 122.78 | I11: =INDEX(VGT[VGT],MATCH(Table_RawData[[#This Row],[Date]],VGT[Date],0)) -> 110.46 | J11: =INDEX(VNQ[VNQ],MATCH(Table_RawData[[#This Row],[Date]],VNQ[Date],0)) -> 79.89 | K11: =INDEX(VXUS[VXUS],MATCH(Table_RawData[[#This Row],[Date]],VXUS[Date],0)) -> 47.09
A12: =EDATE(A11,1) -> 42309 | B12: =INDEX(Table2[Price],MATCH(TimeLine!A12,Table2[Date],0)) -> 101.92 | C12: =INDEX(Table3[Price],MATCH(TimeLine!A12,Table3[Date],0)) -> 81.66 | D12: =INDEX(Table4[Price],MATCH(TimeLine!A12,Table4[Date],0)) -> 208.69 | E12: =INDEX(Table5[Price],MATCH(TimeLine!A12,Table5[Date],0)) -> 66.68 | F12: =INDEX(Table6[Price],MATCH(TimeLine!A12,Table6[Date],0)) -> 0.79 | G12: =INDEX(PG[PG],MATCH(Table_RawData[[#This Row],[Date]],PG[Date],0)) -> 74.84 | H12: =INDEX(TLT[TLT],MATCH(Table_RawData[[#This Row],[Date]],TLT[Date],0)) -> 121.45 | I12: =INDEX(VGT[VGT],MATCH(Table_RawData[[#This Row],[Date]],VGT[Date],0)) -> 111.77 | J12: =INDEX(VNQ[VNQ],MATCH(Table_RawData[[#This Row],[Date]],VNQ[Date],0)) -> 79.39 | K12: =INDEX(VXUS[VXUS],MATCH(Table_RawData[[#This Row],[Date]],VXUS[Date],0)) -> 46.47
A13: =EDATE(A12,1) -> 42339 | B13: =INDEX(Table2[Price],MATCH(TimeLine!A13,Table2[Date],0)) -> 101.46 | C13: =INDEX(Table3[Price],MATCH(TimeLine!A13,Table3[Date],0)) -> 77.95 | D13: =INDEX(Table4[Price],MATCH(TimeLine!A13,Table4[Date],0)) -> 203.87 | E13: =INDEX(Table5[Price],MATCH(TimeLine!A13,Table5[Date],0)) -> 66.03 | F13: =INDEX(Table6[Price],MATCH(TimeLine!A13,Table6[Date],0)) -> 0.82 | G13: =INDEX(PG[PG],MATCH(Table_RawData[[#This Row],[Date]],PG[Date],0)) -> 79.41 | H13: =INDEX(TLT[TLT],MATCH(Table_RawData[[#This Row],[Date]],TLT[Date],0)) -> 120.58 | I13: =INDEX(VGT[VGT],MATCH(Table_RawData[[#This Row],[Date]],VGT[Date],0)) -> 108.29 | J13: =INDEX(VNQ[VNQ],MATCH(Table_RawData[[#This Row],[Date]],VNQ[Date],0)) -> 79.73 | K13: =INDEX(VXUS[VXUS],MATCH(Table_RawData[[#This Row],[Date]],VXUS[Date],0)) -> 45.11
A14: =EDATE(A13,1) -> 42370 | B14: =INDEX(Table2[Price],MATCH(TimeLine!A14,Table2[Date],0)) -> 106.95 | C14: =INDEX(Table3[Price],MATCH(TimeLine!A14,Table3[Date],0)) -> 77.85 | D14: =INDEX(Table4[Price],MATCH(TimeLine!A14,Table4[Date],0)) -> 193.72 | E14: =INDEX(Table5[Price],MATCH(TimeLine!A14,Table5[Date],0)) -> 59.5 | F14: =INDEX(Table6[Price],MATCH(TimeLine!A14,Table6[Date],0)) -> 0.73 | G14: =INDEX(PG[PG],MATCH(Table_RawData[[#This Row],[Date]],PG[Date],0)) -> 81.69 | H14: =INDEX(TLT[TLT],MATCH(Table_RawData[[#This Row],[Date]],TLT[Date],0)) -> 127.3 | I14: =INDEX(VGT[VGT],MATCH(Table_RawData[[#This Row],[Date]],VGT[Date],0)) -> 101.93 | J14: =INDEX(VNQ[VNQ],MATCH(Table_RawData[[#This Row],[Date]],VNQ[Date],0)) -> 76.99 | K14: =INDEX(VXUS[VXUS],MATCH(Table_RawData[[#This Row],[Date]],VXUS[Date],0)) -> 42.65
... A134: =EDATE(A133,1) -> 46023 | B134: =INDEX(Table2[Price],MATCH(TimeLine!A134,Table2[Date],0)) -> 421.29 | C134: =INDEX(Table3[Price],MATCH(TimeLine!A134,Table3[Date],0)) -> 129.89 | D134: =INDEX(Table4[Price],MATCH(TimeLine!A134,Table4[Date],0)) -> 691.66 | E134: =INDEX(Table5[Price],MATCH(TimeLine!A134,Table5[Date],0)) -> 312.47 | F134: =INDEX(Table6[Price],MATCH(TimeLine!A134,Table6[Date],0)) -> 186.23 | G134: =INDEX(PG[PG],MATCH(Table_RawData[[#This Row],[Date]],PG[Date],0)) -> 150.15 | H134: =INDEX(TLT[TLT],MATCH(Table_RawData[[#This Row],[Date]],TLT[Date],0)) -> 87.63 | I134: =INDEX(VGT[VGT],MATCH(Table_RawData[[#This Row],[Date]],VGT[Date],0)) -> 753.57 | J134: =INDEX(VNQ[VNQ],MATCH(Table_RawData[[#This Row],[Date]],VNQ[Date],0)) -> 90.37 | K134: =INDEX(VXUS[VXUS],MATCH(Table_RawData[[#This Row],[Date]],VXUS[Date],0)) -> 79.53
A135: Total | B135: =COUNT(Table_RawData[GLD]) -> 133 | C135: =COUNT(Table_RawData[XOM]) -> 133 | D135: =COUNT(Table_RawData[SPY]) -> 133 | E135: =COUNT(Table_RawData[JPM]) -> 133 | F135: =COUNT(Table_RawData[NVDA]) -> 133 | G135: =COUNT(Table_RawData[PG]) -> 133 | H135: =COUNT(Table_RawData[TLT]) -> 133 | I135: =COUNT(Table_RawData[VGT]) -> 133 | J135: =COUNT(Table_RawData[VNQ]) -> 133 | K135: =COUNT(Table_RawData[VXUS]) -> 133

Sheet Returns
A1: Monthly Returns
A2: Date | B2: GLD | C2: XOM | D2: SPY | E2: JPM | F2: NVDA | G2: PG | H2: TLT | I2: VGT | J2: VNQ | K2: VXUS
A3: =TimeLine!A3 -> 42036 | B3: =IFERROR((TimeLine!B3/TimeLine!B2)-1, NA()) -> -0.059052248 | C3: =IFERROR((TimeLine!C3/TimeLine!C2)-1, NA()) -> 0.012811714 | D3: =IFERROR((TimeLine!D3/TimeLine!D2)-1, NA()) -> 0.056204563 | E3: =IFERROR((TimeLine!E3/TimeLine!E2)-1, NA()) -> 0.12688488 | F3: =IFERROR((TimeLine!F3/TimeLine!F2)-1, NA()) -> 0.14583333 | G3: =IFERROR((TimeLine!G3/TimeLine!G2)-1, NA()) -> 0.009965595 | H3: =IFERROR((TimeLine!H3/TimeLine!H2)-1, NA()) -> -0.063277408 | I3: =IFERROR((TimeLine!I3/TimeLine!I2)-1, NA()) -> 0.083325067 | ... K3: =IFERROR((TimeLine!K3/TimeLine!K2)-1, NA()) -> 0.057767691
A4: =TimeLine!A4 -> 42064 | B4: =IFERROR((TimeLine!B4/TimeLine!B3)-1, NA()) -> -0.021522039 | C4: =IFERROR((TimeLine!C4/TimeLine!C3)-1, NA()) -> -0.039981929 | D4: =IFERROR((TimeLine!D4/TimeLine!D3)-1, NA()) -> -0.020079749 | E4: =IFERROR((TimeLine!E4/TimeLine!E3)-1, NA()) -> -0.011422977 | F4: =IFERROR((TimeLine!F4/TimeLine!F3)-1, NA()) -> -0.054545455 | G4: =IFERROR((TimeLine!G4/TimeLine!G3)-1, NA()) -> -0.037472101 | H4: =IFERROR((TimeLine!H4/TimeLine!H3)-1, NA()) -> 0.0089554543 | I4: =IFERROR((TimeLine!I4/TimeLine!I3)-1, NA()) -> -0.024631444 | ... K4: =IFERROR((TimeLine!K4/TimeLine!K3)-1, NA()) -> -0.017944217
A5: =TimeLine!A5 -> 42095 | B5: =IFERROR((TimeLine!B5/TimeLine!B4)-1, NA()) -> -0.0016716523 | C5: =IFERROR((TimeLine!C5/TimeLine!C4)-1, NA()) -> 0.027882353 | D5: =IFERROR((TimeLine!D5/TimeLine!D4)-1, NA()) -> 0.009833842 | E5: =IFERROR((TimeLine!E5/TimeLine!E4)-1, NA()) -> 0.044239023 | F5: =IFERROR((TimeLine!F5/TimeLine!F4)-1, NA()) -> 0.057692308 | G5: =IFERROR((TimeLine!G5/TimeLine!G4)-1, NA()) -> -0.029655846 | H5: =IFERROR((TimeLine!H5/TimeLine!H4)-1, NA()) -> -0.036269034 | I5: =IFERROR((TimeLine!I5/TimeLine!I4)-1, NA()) -> 0.012861434 | ... K5: =IFERROR((TimeLine!K5/TimeLine!K4)-1, NA()) -> 0.048063555
A6: =TimeLine!A6 -> 42125 | B6: =IFERROR((TimeLine!B6/TimeLine!B5)-1, NA()) -> 0.0055521283 | C6: =IFERROR((TimeLine!C6/TimeLine!C5)-1, NA()) -> -0.024836901 | D6: =IFERROR((TimeLine!D6/TimeLine!D5)-1, NA()) -> 0.012856183 | E6: =IFERROR((TimeLine!E6/TimeLine!E5)-1, NA()) -> 0.039835599 | F6: =IFERROR((TimeLine!F6/TimeLine!F5)-1, NA()) -> 0 | G6: =IFERROR((TimeLine!G6/TimeLine!G5)-1, NA()) -> -0.014086278 | H6: =IFERROR((TimeLine!H6/TimeLine!H5)-1, NA()) -> -0.025724494 | I6: =IFERROR((TimeLine!I6/TimeLine!I5)-1, NA()) -> 0.024932802 | ... K6: =IFERROR((TimeLine!K6/TimeLine!K5)-1, NA()) -> -0.0090960773
A7: =TimeLine!A7 -> 42156 | B7: =IFERROR((TimeLine!B7/TimeLine!B6)-1, NA()) -> -0.015162138 | C7: =IFERROR((TimeLine!C7/TimeLine!C6)-1, NA()) -> -0.023474178 | D7: =IFERROR((TimeLine!D7/TimeLine!D6)-1, NA()) -> -0.025054466 | E7: =IFERROR((TimeLine!E7/TimeLine!E6)-1, NA()) -> 0.030100334 | F7: =IFERROR((TimeLine!F7/TimeLine!F6)-1, NA()) -> -0.090909091 | G7: =IFERROR((TimeLine!G7/TimeLine!G6)-1, NA()) -> -0.0019135094 | H7: =IFERROR((TimeLine!H7/TimeLine!H6)-1, NA()) -> -0.042783799 | I7: =IFERROR((TimeLine!I7/TimeLine!I6)-1, NA()) -> -0.039338036 | ... K7: =IFERROR((TimeLine!K7/TimeLine!K6)-1, NA()) -> -0.037483266
A8: =TimeLine!A8 -> 42186 | B8: =IFERROR((TimeLine!B8/TimeLine!B7)-1, NA()) -> -0.066209842 | C8: =IFERROR((TimeLine!C8/TimeLine!C7)-1, NA()) -> -0.047956731 | D8: =IFERROR((TimeLine!D8/TimeLine!D7)-1, NA()) -> 0.022589264 | E8: =IFERROR((TimeLine!E8/TimeLine!E7)-1, NA()) -> 0.011363636 | F8: =IFERROR((TimeLine!F8/TimeLine!F7)-1, NA()) -> 0 | G8: =IFERROR((TimeLine!G8/TimeLine!G7)-1, NA()) -> -0.019683027 | H8: =IFERROR((TimeLine!H8/TimeLine!H7)-1, NA()) -> 0.04316363 | I8: =IFERROR((TimeLine!I8/TimeLine!I7)-1, NA()) -> 0.022686623 | ... K8: =IFERROR((TimeLine!K8/TimeLine!K7)-1, NA()) -> -0.0055632823
A9: =TimeLine!A9 -> 42217 | B9: =IFERROR((TimeLine!B9/TimeLine!B8)-1, NA()) -> 0.037072334 | C9: =IFERROR((TimeLine!C9/TimeLine!C8)-1, NA()) -> -0.050119934 | D9: =IFERROR((TimeLine!D9/TimeLine!D8)-1, NA()) -> -0.060950119 | E9: =IFERROR((TimeLine!E9/TimeLine!E8)-1, NA()) -> -0.064643222 | F9: =IFERROR((TimeLine!F9/TimeLine!F8)-1, NA()) -> 0.12 | G9: =IFERROR((TimeLine!G9/TimeLine!G8)-1, NA()) -> -0.078617992 | H9: =IFERROR((TimeLine!H9/TimeLine!H8)-1, NA()) -> -0.009059006 | I9: =IFERROR((TimeLine!I9/TimeLine!I8)-1, NA()) -> -0.057989691 | ... K9: =IFERROR((TimeLine!K9/TimeLine!K8)-1, NA()) -> -0.074325674
A10: =TimeLine!A10 -> 42248 | B10: =IFERROR((TimeLine!B10/TimeLine!B9)-1, NA()) -> -0.018011395 | C10: =IFERROR((TimeLine!C10/TimeLine!C9)-1, NA()) -> -0.011828814 | D10: =IFERROR((TimeLine!D10/TimeLine!D9)-1, NA()) -> -0.030555977 | E10: =IFERROR((TimeLine!E10/TimeLine!E9)-1, NA()) -> -0.048829953 | F10: =IFERROR((TimeLine!F10/TimeLine!F9)-1, NA()) -> 0.10714286 | G10: =IFERROR((TimeLine!G10/TimeLine!G9)-1, NA()) -> 0.01797085 | H10: =IFERROR((TimeLine!H10/TimeLine!H9)-1, NA()) -> 0.017460056 | I10: =IFERROR((TimeLine!I10/TimeLine!I9)-1, NA()) -> -0.02286496 | ... K10: =IFERROR((TimeLine!K10/TimeLine!K9)-1, NA()) -> -0.043384416
A11: =TimeLine!A11 -> 42278 | B11: =IFERROR((TimeLine!B11/TimeLine!B10)-1, NA()) -> 0.022833614 | C11: =IFERROR((TimeLine!C11/TimeLine!C10)-1, NA()) -> 0.11284465 | D11: =IFERROR((TimeLine!D11/TimeLine!D10)-1, NA()) -> 0.085059751 | E11: =IFERROR((TimeLine!E11/TimeLine!E10)-1, NA()) -> 0.053796949 | F11: =IFERROR((TimeLine!F11/TimeLine!F10)-1, NA()) -> 0.14516129 | G11: =IFERROR((TimeLine!G11/TimeLine!G10)-1, NA()) -> 0.061718098 | H11: =IFERROR((TimeLine!H11/TimeLine!H10)-1, NA()) -> -0.0061518537 | I11: =IFERROR((TimeLine!I11/TimeLine!I10)-1, NA()) -> 0.1046 | ... K11: =IFERROR((TimeLine!K11/TimeLine!K10)-1, NA()) -> 0.0625
A12: =TimeLine!A12 -> 42309 | B12: =IFERROR((TimeLine!B12/TimeLine!B11)-1, NA()) -> -0.067520586 | C12: =IFERROR((TimeLine!C12/TimeLine!C11)-1, NA()) -> -0.013052937 | D12: =IFERROR((TimeLine!D12/TimeLine!D11)-1, NA()) -> 0.0036550762 | E12: =IFERROR((TimeLine!E12/TimeLine!E11)-1, NA()) -> 0.037821012 | F12: =IFERROR((TimeLine!F12/TimeLine!F11)-1, NA()) -> 0.11267606 | G12: =IFERROR((TimeLine!G12/TimeLine!G11)-1, NA()) -> -0.020162346 | H12: =IFERROR((TimeLine!H12/TimeLine!H11)-1, NA()) -> -0.010832383 | I12: =IFERROR((TimeLine!I12/TimeLine!I11)-1, NA()) -> 0.011859497 | ... K12: =IFERROR((TimeLine!K12/TimeLine!K11)-1, NA()) -> -0.013166277
A13: =TimeLine!A13 -> 42339 | B13: =IFERROR((TimeLine!B13/TimeLine!B12)-1, NA()) -> -0.0045133438 | C13: =IFERROR((TimeLine!C13/TimeLine!C12)-1, NA()) -> -0.04543228 | D13: =IFERROR((TimeLine!D13/TimeLine!D12)-1, NA()) -> -0.023096459 | E13: =IFERROR((TimeLine!E13/TimeLine!E12)-1, NA()) -> -0.0097480504 | F13: =IFERROR((TimeLine!F13/TimeLine!F12)-1, NA()) -> 0.037974684 | G13: =IFERROR((TimeLine!G13/TimeLine!G12)-1, NA()) -> 0.061063602 | H13: =IFERROR((TimeLine!H13/TimeLine!H12)-1, NA()) -> -0.0071634417 | I13: =IFERROR((TimeLine!I13/TimeLine!I12)-1, NA()) -> -0.031135367 | ... K13: =IFERROR((TimeLine!K13/TimeLine!K12)-1, NA()) -> -0.029266193
A14: =TimeLine!A14 -> 42370 | B14: =IFERROR((TimeLine!B14/TimeLine!B13)-1, NA()) -> 0.054109994 | C14: =IFERROR((TimeLine!C14/TimeLine!C13)-1, NA()) -> -0.0012828736 | D14: =IFERROR((TimeLine!D14/TimeLine!D13)-1, NA()) -> -0.049786629 | E14: =IFERROR((TimeLine!E14/TimeLine!E13)-1, NA()) -> -0.098894442 | F14: =IFERROR((TimeLine!F14/TimeLine!F13)-1, NA()) -> -0.1097561 | G14: =IFERROR((TimeLine!G14/TimeLine!G13)-1, NA()) -> 0.028711749 | H14: =IFERROR((TimeLine!H14/TimeLine!H13)-1, NA()) -> 0.055730635 | I14: =IFERROR((TimeLine!I14/TimeLine!I13)-1, NA()) -> -0.058731185 | ... K14: =IFERROR((TimeLine!K14/TimeLine!K13)-1, NA()) -> -0.054533363
... A134: =TimeLine!A134 -> 46023 | B134: =IFERROR((TimeLine!B134/TimeLine!B133)-1, NA()) -> 0.063031465 | C134: =IFERROR((TimeLine!C134/TimeLine!C133)-1, NA()) -> 0.079358484 | D134: =IFERROR((TimeLine!D134/TimeLine!D133)-1, NA()) -> 0.0142832 | E134: =IFERROR((TimeLine!E134/TimeLine!E133)-1, NA()) -> -0.030258829 | F134: =IFERROR((TimeLine!F134/TimeLine!F133)-1, NA()) -> -0.0014477212 | G134: =IFERROR((TimeLine!G134/TimeLine!G133)-1, NA()) -> 0.0477287 | H134: =IFERROR((TimeLine!H134/TimeLine!H133)-1, NA()) -> 0.0053923818 | I134: =IFERROR((TimeLine!I134/TimeLine!I133)-1, NA()) -> -0.00027859588 | ... K134: =IFERROR((TimeLine!K134/TimeLine!K133)-1, NA()) -> 0.05421527

Sheet Returns2
A1: Date | B1: GLD | C1: XOM | D1: SPY | E1: JPM | F1: NVDA | G1: PG | H1: TLT | I1: VGT | J1: VNQ | K1: VXUS
A2: =TimeLine!A3 -> 42036 | B2: =IFERROR((TimeLine!B3/TimeLine!B2)-1, NA()) -> -0.059052248 | C2: =IFERROR((TimeLine!C3/TimeLine!C2)-1, NA()) -> 0.012811714 | D2: =IFERROR((TimeLine!D3/TimeLine!D2)-1, NA()) -> 0.056204563 | E2: =IFERROR((TimeLine!E3/TimeLine!E2)-1, NA()) -> 0.12688488 | F2: =IFERROR((TimeLine!F3/TimeLine!F2)-1, NA()) -> 0.14583333 | G2: =IFERROR((TimeLine!G3/TimeLine!G2)-1, NA()) -> 0.009965595 | H2: =IFERROR((TimeLine!H3/TimeLine!H2)-1, NA()) -> -0.063277408 | I2: =IFERROR((TimeLine!I3/TimeLine!I2)-1, NA()) -> 0.083325067 | ... K2: =IFERROR((TimeLine!K3/TimeLine!K2)-1, NA()) -> 0.057767691
A3: =TimeLine!A4 -> 42064 | B3: =IFERROR((TimeLine!B4/TimeLine!B3)-1, NA()) -> -0.021522039 | C3: =IFERROR((TimeLine!C4/TimeLine!C3)-1, NA()) -> -0.039981929 | D3: =IFERROR((TimeLine!D4/TimeLine!D3)-1, NA()) -> -0.020079749 | E3: =IFERROR((TimeLine!E4/TimeLine!E3)-1, NA()) -> -0.011422977 | F3: =IFERROR((TimeLine!F4/TimeLine!F3)-1, NA()) -> -0.054545455 | G3: =IFERROR((TimeLine!G4/TimeLine!G3)-1, NA()) -> -0.037472101 | H3: =IFERROR((TimeLine!H4/TimeLine!H3)-1, NA()) -> 0.0089554543 | I3: =IFERROR((TimeLine!I4/TimeLine!I3)-1, NA()) -> -0.024631444 | ... K3: =IFERROR((TimeLine!K4/TimeLine!K3)-1, NA()) -> -0.017944217
A4: =TimeLine!A5 -> 42095 | B4: =IFERROR((TimeLine!B5/TimeLine!B4)-1, NA()) -> -0.0016716523 | C4: =IFERROR((TimeLine!C5/TimeLine!C4)-1, NA()) -> 0.027882353 | D4: =IFERROR((TimeLine!D5/TimeLine!D4)-1, NA()) -> 0.009833842 | E4: =IFERROR((TimeLine!E5/TimeLine!E4)-1, NA()) -> 0.044239023 | F4: =IFERROR((TimeLine!F5/TimeLine!F4)-1, NA()) -> 0.057692308 | G4: =IFERROR((TimeLine!G5/TimeLine!G4)-1, NA()) -> -0.029655846 | H4: =IFERROR((TimeLine!H5/TimeLine!H4)-1, NA()) -> -0.036269034 | I4: =IFERROR((TimeLine!I5/TimeLine!I4)-1, NA()) -> 0.012861434 | ... K4: =IFERROR((TimeLine!K5/TimeLine!K4)-1, NA()) -> 0.048063555
A5: =TimeLine!A6 -> 42125 | B5: =IFERROR((TimeLine!B6/TimeLine!B5)-1, NA()) -> 0.0055521283 | C5: =IFERROR((TimeLine!C6/TimeLine!C5)-1, NA()) -> -0.024836901 | D5: =IFERROR((TimeLine!D6/TimeLine!D5)-1, NA()) -> 0.012856183 | E5: =IFERROR((TimeLine!E6/TimeLine!E5)-1, NA()) -> 0.039835599 | F5: =IFERROR((TimeLine!F6/TimeLine!F5)-1, NA()) -> 0 | G5: =IFERROR((TimeLine!G6/TimeLine!G5)-1, NA()) -> -0.014086278 | H5: =IFERROR((TimeLine!H6/TimeLine!H5)-1, NA()) -> -0.025724494 | I5: =IFERROR((TimeLine!I6/TimeLine!I5)-1, NA()) -> 0.024932802 | ... K5: =IFERROR((TimeLine!K6/TimeLine!K5)-1, NA()) -> -0.0090960773
A6: =TimeLine!A7 -> 42156 | B6: =IFERROR((TimeLine!B7/TimeLine!B6)-1, NA()) -> -0.015162138 | C6: =IFERROR((TimeLine!C7/TimeLine!C6)-1, NA()) -> -0.023474178 | D6: =IFERROR((TimeLine!D7/TimeLine!D6)-1, NA()) -> -0.025054466 | E6: =IFERROR((TimeLine!E7/TimeLine!E6)-1, NA()) -> 0.030100334 | F6: =IFERROR((TimeLine!F7/TimeLine!F6)-1, NA()) -> -0.090909091 | G6: =IFERROR((TimeLine!G7/TimeLine!G6)-1, NA()) -> -0.0019135094 | H6: =IFERROR((TimeLine!H7/TimeLine!H6)-1, NA()) -> -0.042783799 | I6: =IFERROR((TimeLine!I7/TimeLine!I6)-1, NA()) -> -0.039338036 | ... K6: =IFERROR((TimeLine!K7/TimeLine!K6)-1, NA()) -> -0.037483266
A7: =TimeLine!A8 -> 42186 | B7: =IFERROR((TimeLine!B8/TimeLine!B7)-1, NA()) -> -0.066209842 | C7: =IFERROR((TimeLine!C8/TimeLine!C7)-1, NA()) -> -0.047956731 | D7: =IFERROR((TimeLine!D8/TimeLine!D7)-1, NA()) -> 0.022589264 | E7: =IFERROR((TimeLine!E8/TimeLine!E7)-1, NA()) -> 0.011363636 | F7: =IFERROR((TimeLine!F8/TimeLine!F7)-1, NA()) -> 0 | G7: =IFERROR((TimeLine!G8/TimeLine!G7)-1, NA()) -> -0.019683027 | H7: =IFERROR((TimeLine!H8/TimeLine!H7)-1, NA()) -> 0.04316363 | I7: =IFERROR((TimeLine!I8/TimeLine!I7)-1, NA()) -> 0.022686623 | ... K7: =IFERROR((TimeLine!K8/TimeLine!K7)-1, NA()) -> -0.0055632823
A8: =TimeLine!A9 -> 42217 | B8: =IFERROR((TimeLine!B9/TimeLine!B8)-1, NA()) -> 0.037072334 | C8: =IFERROR((TimeLine!C9/TimeLine!C8)-1, NA()) -> -0.050119934 | D8: =IFERROR((TimeLine!D9/TimeLine!D8)-1, NA()) -> -0.060950119 | E8: =IFERROR((TimeLine!E9/TimeLine!E8)-1, NA()) -> -0.064643222 | F8: =IFERROR((TimeLine!F9/TimeLine!F8)-1, NA()) -> 0.12 | G8: =IFERROR((TimeLine!G9/TimeLine!G8)-1, NA()) -> -0.078617992 | H8: =IFERROR((TimeLine!H9/TimeLine!H8)-1, NA()) -> -0.009059006 | I8: =IFERROR((TimeLine!I9/TimeLine!I8)-1, NA()) -> -0.057989691 | ... K8: =IFERROR((TimeLine!K9/TimeLine!K8)-1, NA()) -> -0.074325674
A9: =TimeLine!A10 -> 42248 | B9: =IFERROR((TimeLine!B10/TimeLine!B9)-1, NA()) -> -0.018011395 | C9: =IFERROR((TimeLine!C10/TimeLine!C9)-1, NA()) -> -0.011828814 | D9: =IFERROR((TimeLine!D10/TimeLine!D9)-1, NA()) -> -0.030555977 | E9: =IFERROR((TimeLine!E10/TimeLine!E9)-1, NA()) -> -0.048829953 | F9: =IFERROR((TimeLine!F10/TimeLine!F9)-1, NA()) -> 0.10714286 | G9: =IFERROR((TimeLine!G10/TimeLine!G9)-1, NA()) -> 0.01797085 | H9: =IFERROR((TimeLine!H10/TimeLine!H9)-1, NA()) -> 0.017460056 | I9: =IFERROR((TimeLine!I10/TimeLine!I9)-1, NA()) -> -0.02286496 | ... K9: =IFERROR((TimeLine!K10/TimeLine!K9)-1, NA()) -> -0.043384416
A10: =TimeLine!A11 -> 42278 | B10: =IFERROR((TimeLine!B11/TimeLine!B10)-1, NA()) -> 0.022833614 | C10: =IFERROR((TimeLine!C11/TimeLine!C10)-1, NA()) -> 0.11284465 | D10: =IFERROR((TimeLine!D11/TimeLine!D10)-1, NA()) -> 0.085059751 | E10: =IFERROR((TimeLine!E11/TimeLine!E10)-1, NA()) -> 0.053796949 | F10: =IFERROR((TimeLine!F11/TimeLine!F10)-1, NA()) -> 0.14516129 | G10: =IFERROR((TimeLine!G11/TimeLine!G10)-1, NA()) -> 0.061718098 | H10: =IFERROR((TimeLine!H11/TimeLine!H10)-1, NA()) -> -0.0061518537 | I10: =IFERROR((TimeLine!I11/TimeLine!I10)-1, NA()) -> 0.1046 | ... K10: =IFERROR((TimeLine!K11/TimeLine!K10)-1, NA()) -> 0.0625
A11: =TimeLine!A12 -> 42309 | B11: =IFERROR((TimeLine!B12/TimeLine!B11)-1, NA()) -> -0.067520586 | C11: =IFERROR((TimeLine!C12/TimeLine!C11)-1, NA()) -> -0.013052937 | D11: =IFERROR((TimeLine!D12/TimeLine!D11)-1, NA()) -> 0.0036550762 | E11: =IFERROR((TimeLine!E12/TimeLine!E11)-1, NA()) -> 0.037821012 | F11: =IFERROR((TimeLine!F12/TimeLine!F11)-1, NA()) -> 0.11267606 | G11: =IFERROR((TimeLine!G12/TimeLine!G11)-1, NA()) -> -0.020162346 | H11: =IFERROR((TimeLine!H12/TimeLine!H11)-1, NA()) -> -0.010832383 | I11: =IFERROR((TimeLine!I12/TimeLine!I11)-1, NA()) -> 0.011859497 | ... K11: =IFERROR((TimeLine!K12/TimeLine!K11)-1, NA()) -> -0.013166277
A12: =TimeLine!A13 -> 42339 | B12: =IFERROR((TimeLine!B13/TimeLine!B12)-1, NA()) -> -0.0045133438 | C12: =IFERROR((TimeLine!C13/TimeLine!C12)-1, NA()) -> -0.04543228 | D12: =IFERROR((TimeLine!D13/TimeLine!D12)-1, NA()) -> -0.023096459 | E12: =IFERROR((TimeLine!E13/TimeLine!E12)-1, NA()) -> -0.0097480504 | F12: =IFERROR((TimeLine!F13/TimeLine!F12)-1, NA()) -> 0.037974684 | G12: =IFERROR((TimeLine!G13/TimeLine!G12)-1, NA()) -> 0.061063602 | H12: =IFERROR((TimeLine!H13/TimeLine!H12)-1, NA()) -> -0.0071634417 | I12: =IFERROR((TimeLine!I13/TimeLine!I12)-1, NA()) -> -0.031135367 | ... K12: =IFERROR((TimeLine!K13/TimeLine!K12)-1, NA()) -> -0.029266193
A13: =TimeLine!A14 -> 42370 | B13: =IFERROR((TimeLine!B14/TimeLine!B13)-1, NA()) -> 0.054109994 | C13: =IFERROR((TimeLine!C14/TimeLine!C13)-1, NA()) -> -0.0012828736 | D13: =IFERROR((TimeLine!D14/TimeLine!D13)-1, NA()) -> -0.049786629 | E13: =IFERROR((TimeLine!E14/TimeLine!E13)-1, NA()) -> -0.098894442 | F13: =IFERROR((TimeLine!F14/TimeLine!F13)-1, NA()) -> -0.1097561 | G13: =IFERROR((TimeLine!G14/TimeLine!G13)-1, NA()) -> 0.028711749 | H13: =IFERROR((TimeLine!H14/TimeLine!H13)-1, NA()) -> 0.055730635 | I13: =IFERROR((TimeLine!I14/TimeLine!I13)-1, NA()) -> -0.058731185 | ... K13: =IFERROR((TimeLine!K14/TimeLine!K13)-1, NA()) -> -0.054533363
... A133: =TimeLine!A134 -> 46023 | B133: =IFERROR((TimeLine!B134/TimeLine!B133)-1, NA()) -> 0.063031465 | C133: =IFERROR((TimeLine!C134/TimeLine!C133)-1, NA()) -> 0.079358484 | D133: =IFERROR((TimeLine!D134/TimeLine!D133)-1, NA()) -> 0.0142832 | E133: =IFERROR((TimeLine!E134/TimeLine!E133)-1, NA()) -> -0.030258829 | F133: =IFERROR((TimeLine!F134/TimeLine!F133)-1, NA()) -> -0.0014477212 | G133: =IFERROR((TimeLine!G134/TimeLine!G133)-1, NA()) -> 0.0477287 | H133: =IFERROR((TimeLine!H134/TimeLine!H133)-1, NA()) -> 0.0053923818 | I133: =IFERROR((TimeLine!I134/TimeLine!I133)-1, NA()) -> -0.00027859588 | ... K133: =IFERROR((TimeLine!K134/TimeLine!K133)-1, NA()) -> 0.05421527

Sheet Risk_Analysis
A1: Risk & Return
A2: Metric | B2: GLD | C2: XOM | D2: SPY | E2: JPM | F2: NVDA | G2: PG | H2: TLT | I2: VGT | J2: VNQ | K2: VXUS
A3: Mean (Monthly) | B3: =AVERAGE(Returns!B3:B134) -> 0.010176236 | C3: =AVERAGE(Returns!C3:C134) -> 0.0058544244 | D3: =AVERAGE(Returns!D3:D134) -> 0.010405797 | E3: =AVERAGE(Returns!E3:E134) -> 0.015624227 | F3: =AVERAGE(Returns!F3:F134) -> 0.054681936 | G3: =AVERAGE(Returns!G3:G134) -> 0.0054087935 | H3: =AVERAGE(Returns!H3:H134) -> -0.0027144972 | I3: =AVERAGE(Returns!I3:I134) -> 0.016933095 | ... K3: =AVERAGE(Returns!K3:K134) -> 0.0046811889
A4: Std Dev (Monthly) | B4: =_xlfn.STDEV.S(Returns!B3:B134) -> 0.041340507 | C4: =_xlfn.STDEV.S(Returns!C3:C134) -> 0.076034359 | D4: =_xlfn.STDEV.S(Returns!D3:D134) -> 0.043432228 | E4: =_xlfn.STDEV.S(Returns!E3:E134) -> 0.067971877 | F4: =_xlfn.STDEV.S(Returns!F3:F134) -> 0.13247904 | G4: =_xlfn.STDEV.S(Returns!G3:G134) -> 0.045545855 | H4: =_xlfn.STDEV.S(Returns!H3:H134) -> 0.038526618 | I4: =_xlfn.STDEV.S(Returns!I3:I134) -> 0.056523773 | ... K4: =_xlfn.STDEV.S(Returns!K3:K134) -> 0.04292215
A5: Mean (Annualized) | B5: =B3*12 -> 0.12211484 | C5: =C3*12 -> 0.070253093 | D5: =D3*12 -> 0.12486957 | E5: =E3*12 -> 0.18749072 | F5: =F3*12 -> 0.65618323 | G5: =G3*12 -> 0.064905522 | H5: =H3*12 -> -0.032573967 | I5: =I3*12 -> 0.20319714 | ... K5: =K3*12 -> 0.056174267
A6: Std Dev (Annualized) | B6: =B4*SQRT(12) -> 0.14320772 | C6: =C4*SQRT(12) -> 0.26339074 | D6: =D4*SQRT(12) -> 0.15045365 | E6: =E4*SQRT(12) -> 0.23546149 | F6: =F4*SQRT(12) -> 0.45892084 | G6: =G4*SQRT(12) -> 0.15777547 | H6: =H4*SQRT(12) -> 0.13346012 | I6: =I4*SQRT(12) -> 0.19580409 | ... K6: =K4*SQRT(12) -> 0.14868669
A7: Sharpe Ratio | B7: =(B5-Risk_Free_rate)/B6 -> 0.57339672 | C7: =(C5-Risk_Free_rate)/C6 -> 0.11486012 | D7: =(D5-Risk_Free_rate)/D6 -> 0.56409112 | E7: =(E5-Risk_Free_rate)/E6 -> 0.62639001 | F7: =(F5-Risk_Free_rate)/F6 -> 1.3426787 | G7: =(G5-Risk_Free_rate)/G6 -> 0.15785421 | H7: =(H5-Risk_Free_rate)/H6 -> -0.54378766 | I7: =(I5-Risk_Free_rate)/I6 -> 0.83347153 | ... K7: =(K5-Risk_Free_rate)/K6 -> 0.10878087
A13: Risk-Free Rate | B13: 0.04

Sheet Correlation
A1: correlation matrix
B2: GLD | C2: XOM | D2: SPY | E2: JPM | F2: NVDA | G2: PG | H2: TLT | I2: VGT | J2: VNQ | K2: VXUS
A3: GLD | B3: 1
A4: XOM | B4: -0.052602678 | C4: 1
A5: SPY | B5: 0.075629895 | C5: 0.48664066 | D5: 1
A6: JPM | B6: -0.15478792 | C6: 0.48366787 | D6: 0.72201194 | E6: 1
A7: NVDA | B7: -0.07135285 | C7: 0.11593509 | D7: 0.58524839 | E7: 0.33253514 | F7: 1
A8: PG | B8: 0.21463343 | C8: 0.15856126 | D8: 0.36666489 | E8: 0.13910832 | F8: 0.0057880811 | G8: 1
A9: TLT | B9: 0.37669484 | C9: -0.21709239 | D9: 0.13737213 | E9: -0.17214217 | F9: 0.14482298 | G9: 0.16097344 | H9: 1
A10: VGT | B10: 0.019545019 | C10: 0.28565349 | D10: 0.90790238 | E10: 0.54603734 | F10: 0.71804122 | G10: 0.24635804 | H10: 0.19899337 | I10: 1
A11: VNQ | B11: 0.16130328 | C11: 0.38133903 | D11: 0.76601496 | E11: 0.47083064 | F11: 0.29478893 | G11: 0.43599369 | H11: 0.4180469 | I11: 0.61115323 | J11: 1
A12: VXUS | B12: 0.23445849 | C12: 0.48602043 | D12: 0.84742524 | E12: 0.67252338 | F12: 0.44102698 | G12: 0.3195242 | H12: 0.15733104 | I12: 0.72499146 | J12: 0.69270347 | K12: 1

Sheet Beta
B1: GLD | C1: XOM | D1: SPY | E1: JPM | F1: NVDA | G1: PG | H1: TLT | I1: VGT | J1: VNQ | K1: VXUS
A2: Beta | B2: =_xlfn.COVARIANCE.S(Returns!B3:B1000, Returns!$D$3:$D$1000) / _xlfn.VAR.S(Returns!$D$3:$D$1000) -> 0.071987516 | C2: =_xlfn.COVARIANCE.S(Returns!C3:C1000, Returns!$D$3:$D$1000) / _xlfn.VAR.S(Returns!$D$3:$D$1000) -> 0.85193442 | D2: =_xlfn.COVARIANCE.S(Returns!D3:D1000, Returns!$D$3:$D$1000) / _xlfn.VAR.S(Returns!$D$3:$D$1000) -> 1 | E2: =_xlfn.COVARIANCE.S(Returns!E3:E1000, Returns!$D$3:$D$1000) / _xlfn.VAR.S(Returns!$D$3:$D$1000) -> 1.129956 | F2: =_xlfn.COVARIANCE.S(Returns!F3:F1000, Returns!$D$3:$D$1000) / _xlfn.VAR.S(Returns!$D$3:$D$1000) -> 1.7851523 | G2: =_xlfn.COVARIANCE.S(Returns!G3:G1000, Returns!$D$3:$D$1000) / _xlfn.VAR.S(Returns!$D$3:$D$1000) -> 0.38450862 | H2: =_xlfn.COVARIANCE.S(Returns!H3:H1000, Returns!$D$3:$D$1000) / _xlfn.VAR.S(Returns!$D$3:$D$1000) -> 0.12185614 | I2: =_xlfn.COVARIANCE.S(Returns!I3:I1000, Returns!$D$3:$D$1000) / _xlfn.VAR.S(Returns!$D$3:$D$1000) -> 1.1815666 | ... K2: =_xlfn.COVARIANCE.S(Returns!K3:K1000, Returns!$D$3:$D$1000) / _xlfn.VAR.S(Returns!$D$3:$D$1000) -> 0.83747288

Sheet Portfolio 
A1: Portfolio Composition
A2: Asset | B2: Weight | C2: Mean (Annualized)
A3: GLD | B3: 0.1 | C3: =INDEX(Risk_Analysis!$B$5:$K$5, MATCH(A3, Risk_Analysis!$B$2:$K$2, 0)) -> 0.12211484
A4: XOM | B4: 0.05 | C4: =INDEX(Risk_Analysis!$B$5:$K$5, MATCH(A4, Risk_Analysis!$B$2:$K$2, 0)) -> 0.070253093
A5: SPY | B5: 0.25 | C5: =INDEX(Risk_Analysis!$B$5:$K$5, MATCH(A5, Risk_Analysis!$B$2:$K$2, 0)) -> 0.12486957
A6: JPM | B6: 0.05 | C6: =INDEX(Risk_Analysis!$B$5:$K$5, MATCH(A6, Risk_Analysis!$B$2:$K$2, 0)) -> 0.18749072
A7: NVDA | B7: 0.05 | C7: =INDEX(Risk_Analysis!$B$5:$K$5, MATCH(A7, Risk_Analysis!$B$2:$K$2, 0)) -> 0.65618323
A8: PG | B8: 0.05 | C8: =INDEX(Risk_Analysis!$B$5:$K$5, MATCH(A8, Risk_Analysis!$B$2:$K$2, 0)) -> 0.064905522
A9: TLT | B9: 0.1 | C9: =INDEX(Risk_Analysis!$B$5:$K$5, MATCH(A9, Risk_Analysis!$B$2:$K$2, 0)) -> -0.032573967
A10: VGT | B10: 0.1 | C10: =INDEX(Risk_Analysis!$B$5:$K$5, MATCH(A10, Risk_Analysis!$B$2:$K$2, 0)) -> 0.20319714
A11: VNQ | B11: 0.1 | C11: =INDEX(Risk_Analysis!$B$5:$K$5, MATCH(A11, Risk_Analysis!$B$2:$K$2, 0)) -> 0.019361355
A12: VXUS | B12: 0.15 | C12: =INDEX(Risk_Analysis!$B$5:$K$5, MATCH(A12, Risk_Analysis!$B$2:$K$2, 0)) -> 0.056174267
A16: Expected Annual Return | B16: =SUMPRODUCT(B3:B12, C3:C12) -> 0.1197951
A20: covariance matrix
B21: GLD | C21: XOM | D21: SPY | E21: JPM | F21: NVDA | G21: PG | H21: TLT | I21: VGT | J21: VNQ | K21: VXUS
A22: GLD | B22: =VARP(Returns!$B$3:$B$134) -> 0.0016960903 | C22: =INDEX($B$22:$K$31, MATCH(C$21, $A$22:$A$31, 0), MATCH($A22, $B$21:$K$21, 0)) -> -0.00016409332 | D22: =INDEX($B$22:$K$31, MATCH(D$21, $A$22:$A$31, 0), MATCH($A22, $B$21:$K$21, 0)) -> 0.00013476552 | E22: =INDEX($B$22:$K$31, MATCH(E$21, $A$22:$A$31, 0), MATCH($A22, $B$21:$K$21, 0)) -> -0.00043165769 | F22: =INDEX($B$22:$K$31, MATCH(F$21, $A$22:$A$31, 0), MATCH($A22, $B$21:$K$21, 0)) -> -0.00038782129 | G22: =INDEX($B$22:$K$31, MATCH(G$21, $A$22:$A$31, 0), MATCH($A22, $B$21:$K$21, 0)) -> 0.00040106929 | H22: =INDEX($B$22:$K$31, MATCH(H$21, $A$22:$A$31, 0), MATCH($A22, $B$21:$K$21, 0)) -> 0.00059542042 | I22: =INDEX($B$22:$K$31, MATCH(I$21, $A$22:$A$31, 0), MATCH($A22, $B$21:$K$21, 0)) -> 4.532527e-05 | J22: =INDEX($B$22:$K$31, MATCH(J$21, $A$22:$A$31, 0), MATCH($A22, $B$21:$K$21, 0)) -> 0.00033398049 | K22: =INDEX($B$22:$K$31, MATCH(K$21, $A$22:$A$31, 0), MATCH($A22, $B$21:$K$21, 0)) -> 0.00041287691
A23: XOM | B23: -0.00016409332 | C23: =VARP(Returns!$C$3:$C$134) -> 0.0057374265 | D23: =INDEX($B$22:$K$31, MATCH(D$21, $A$22:$A$31, 0), MATCH($A23, $B$21:$K$21, 0)) -> 0.001594879 | E23: =INDEX($B$22:$K$31, MATCH(E$21, $A$22:$A$31, 0), MATCH($A23, $B$21:$K$21, 0)) -> 0.0024807543 | F23: =INDEX($B$22:$K$31, MATCH(F$21, $A$22:$A$31, 0), MATCH($A23, $B$21:$K$21, 0)) -> 0.0011589623 | G23: =INDEX($B$22:$K$31, MATCH(G$21, $A$22:$A$31, 0), MATCH($A23, $B$21:$K$21, 0)) -> 0.00054494567 | H23: =INDEX($B$22:$K$31, MATCH(H$21, $A$22:$A$31, 0), MATCH($A23, $B$21:$K$21, 0)) -> -0.00063112117 | I23: =INDEX($B$22:$K$31, MATCH(I$21, $A$22:$A$31, 0), MATCH($A23, $B$21:$K$21, 0)) -> 0.0012183664 | J23: =INDEX($B$22:$K$31, MATCH(J$21, $A$22:$A$31, 0), MATCH($A23, $B$21:$K$21, 0)) -> 0.0014521893 | K23: =INDEX($B$22:$K$31, MATCH(K$21, $A$22:$A$31, 0), MATCH($A23, $B$21:$K$21, 0)) -> 0.0015741396
A24: SPY | B24: 0.00013476552 | C24: 0.001594879 | D24: =VARP(Returns!$D$3:$D$134) -> 0.0018720679 | E24: =INDEX($B$22:$K$31, MATCH(E$21, $A$22:$A$31, 0), MATCH($A24, $B$21:$K$21, 0)) -> 0.0021153543 | F24: =INDEX($B$22:$K$31, MATCH(F$21, $A$22:$A$31, 0), MATCH($A24, $B$21:$K$21, 0)) -> 0.0033419262 | G24: =INDEX($B$22:$K$31, MATCH(G$21, $A$22:$A$31, 0), MATCH($A24, $B$21:$K$21, 0)) -> 0.00071982622 | H24: =INDEX($B$22:$K$31, MATCH(H$21, $A$22:$A$31, 0), MATCH($A24, $B$21:$K$21, 0)) -> 0.00022812296 | I24: =INDEX($B$22:$K$31, MATCH(I$21, $A$22:$A$31, 0), MATCH($A24, $B$21:$K$21, 0)) -> 0.0022119728 | J24: =INDEX($B$22:$K$31, MATCH(J$21, $A$22:$A$31, 0), MATCH($A24, $B$21:$K$21, 0)) -> 0.0016662933 | K24: =INDEX($B$22:$K$31, MATCH(K$21, $A$22:$A$31, 0), MATCH($A24, $B$21:$K$21, 0)) -> 0.0015678061
A25: JPM | B25: -0.00043165769 | C25: 0.0024807543 | D25: 0.0021153543 | E25: =VARP(Returns!$E$3:$E$134) -> 0.0045851747 | F25: =INDEX($B$22:$K$31, MATCH(F$21, $A$22:$A$31, 0), MATCH($A25, $B$21:$K$21, 0)) -> 0.0029717435 | G25: =INDEX($B$22:$K$31, MATCH(G$21, $A$22:$A$31, 0), MATCH($A25, $B$21:$K$21, 0)) -> 0.00042739417 | H25: =INDEX($B$22:$K$31, MATCH(H$21, $A$22:$A$31, 0), MATCH($A25, $B$21:$K$21, 0)) -> -0.00044737816 | I25: =INDEX($B$22:$K$31, MATCH(I$21, $A$22:$A$31, 0), MATCH($A25, $B$21:$K$21, 0)) -> 0.0020819971 | J25: =INDEX($B$22:$K$31, MATCH(J$21, $A$22:$A$31, 0), MATCH($A25, $B$21:$K$21, 0)) -> 0.0016028618 | K25: =INDEX($B$22:$K$31, MATCH(K$21, $A$22:$A$31, 0), MATCH($A25, $B$21:$K$21, 0)) -> 0.001947222
A26: NVDA | B26: -0.00038782129 | C26: 0.0011589623 | D26: 0.0033419262 | E26: 0.0029717435 | F26: =VARP(Returns!$F$3:$F$134) -> 0.017417735 | G26: =INDEX($B$22:$K$31, MATCH(G$21, $A$22:$A$31, 0), MATCH($A26, $B$21:$K$21, 0)) -> 3.4659955e-05 | H26: =INDEX($B$22:$K$31, MATCH(H$21, $A$22:$A$31, 0), MATCH($A26, $B$21:$K$21, 0)) -> 0.00073357227 | I26: =INDEX($B$22:$K$31, MATCH(I$21, $A$22:$A$31, 0), MATCH($A26, $B$21:$K$21, 0)) -> 0.0053361133 | J26: =INDEX($B$22:$K$31, MATCH(J$21, $A$22:$A$31, 0), MATCH($A26, $B$21:$K$21, 0)) -> 0.001955962 | K26: =INDEX($B$22:$K$31, MATCH(K$21, $A$22:$A$31, 0), MATCH($A26, $B$21:$K$21, 0)) -> 0.0024888066
A27: PG | B27: 0.00040106929 | C27: 0.00054494567 | D27: 0.00071982622 | E27: 0.00042739417 | F27: 3.4659955e-05 | G27: =VARP(Returns!$G$3:$G$134) -> 0.0020587096 | H27: =INDEX($B$22:$K$31, MATCH(H$21, $A$22:$A$31, 0), MATCH($A27, $B$21:$K$21, 0)) -> 0.00028032469 | I27: =INDEX($B$22:$K$31, MATCH(I$21, $A$22:$A$31, 0), MATCH($A27, $B$21:$K$21, 0)) -> 0.00062942519 | J27: =INDEX($B$22:$K$31, MATCH(J$21, $A$22:$A$31, 0), MATCH($A27, $B$21:$K$21, 0)) -> 0.0009945604 | K27: =INDEX($B$22:$K$31, MATCH(K$21, $A$22:$A$31, 0), MATCH($A27, $B$21:$K$21, 0)) -> 0.00061991401
A28: TLT | B28: 0.00059542042 | C28: -0.00063112117 | D28: 0.00022812296 | E28: -0.00044737816 | F28: 0.00073357227 | G28: 0.00028032469 | H28: =VARP(Returns!$H$3:$H$134) -> 0.0014730556 | I28: =INDEX($B$22:$K$31, MATCH(I$21, $A$22:$A$31, 0), MATCH($A28, $B$21:$K$21, 0)) -> 0.00043005896 | J28: =INDEX($B$22:$K$31, MATCH(J$21, $A$22:$A$31, 0), MATCH($A28, $B$21:$K$21, 0)) -> 0.00080665529 | K28: =INDEX($B$22:$K$31, MATCH(K$21, $A$22:$A$31, 0), MATCH($A28, $B$21:$K$21, 0)) -> 0.00025819874
A29: VGT | B29: 4.532527e-05 | C29: 0.0012183664 | D29: 0.0022119728 | E29: 0.0020819971 | F29: 0.0053361133 | G29: 0.00062942519 | H29: 0.00043005896 | I29: =VARP(Returns!$I$3:$I$134) -> 0.0031707328 | J29: =INDEX($B$22:$K$31, MATCH(J$21, $A$22:$A$31, 0), MATCH($A29, $B$21:$K$21, 0)) -> 0.0017301484 | K29: =INDEX($B$22:$K$31, MATCH(K$21, $A$22:$A$31, 0), MATCH($A29, $B$21:$K$21, 0)) -> 0.0017455925
A30: VNQ | B30: 0.00033398049 | C30: 0.0014521893 | D30: 0.0016662933 | E30: 0.0016028618 | F30: 0.001955962 | G30: 0.0009945604 | H30: 0.00080665529 | I30: 0.0017301484 | J30: =VARP(Returns!$J$3:$J$134) -> 0.0025275911 | K30: =INDEX($B$22:$K$31, MATCH(K$21, $A$22:$A$31, 0), MATCH($A30, $B$21:$K$21, 0)) -> 0.0014891242
A31: VXUS | B31: 0.00041287691 | C31: 0.0015741396 | D31: 0.0015678061 | E31: 0.001947222 | F31: 0.0024888066 | G31: 0.00061991401 | H31: 0.00025819874 | I31: 0.0017455925 | J31: 0.0014891242 | K31: =VARP(Returns!$K$3:$K$134) -> 0.0018283541
A34: Weight Transpose | B34: {=TRANSPOSE(B3:B12)} -> 0.1 | C34: 0.05 | D34: 0.25 | E34: 0.05 | F34: 0.05 | G34: 0.05 | H34: 0.1 | I34: 0.1 | J34: 0.1 | K34: 0.15
A37: Monthly Variance | B37: =MMULT( MMULT($B$34:$K$34, $B$22:$K$31), $B$3:$B$12 ) -> 0.0013250501
A38: Monthly Volatility | B38: =SQRT(B37) -> 0.036401238
A39: Annualized Volatility | B39: =B38*SQRT(12) -> 0.12609759
A40: Sharpe Ratio | B40: =(B16-Risk_Free_rate)/B39 -> 0.63280431

Sheet Solver_Optimization
E1: Expected Annual Return | F1: Portfolio Sharp | G1: sum of | H1: Risk-Free Rate | I1: Portfolio Volatility (Annualized) | J1: Portfolio Variance (Monthly)
E2: =SUMPRODUCT(B6:B15, C6:C15) -> 0.21181043 | F2: =(E2-H2)/I2 -> 1.1705843 | G2: =SUM(B6:B15) -> 1 | H2: 0.04 | I2: =SQRT(J2)*SQRT(12) -> 0.14677322 | J2: {=MMULT(TRANSPOSE($B$6:$B$15),MMULT($N$3:$W$12,$B$6:$B$15))} -> 0.0017951983 | N2: GLD | O2: XOM | P2: SPY | Q2: JPM | R2: NVDA | S2: PG | T2: TLT | U2: VGT | V2: VNQ | W2: VXUS
M3: GLD | N3: 0.0016960903 | O3: -0.00016409332 | P3: 0.00013476552 | Q3: -0.00043165769 | R3: -0.00038782129 | S3: 0.00040106929 | T3: 0.00059542042 | U3: 4.532527e-05 | V3: 0.00033398049 | W3: 0.00041287691
M4: XOM | N4: -0.00016409332 | O4: 0.0057374265 | P4: 0.001594879 | Q4: 0.0024807543 | R4: 0.0011589623 | S4: 0.00054494567 | T4: -0.00063112117 | U4: 0.0012183664 | V4: 0.0014521893 | W4: 0.0015741396
A5: Asset | B5: Weight | C5: Mean (Annual) | D5: MIN | E5: MAX | M5: SPY | N5: 0.00013476552 | O5: 0.001594879 | P5: 0.0018720679 | Q5: 0.0021153543 | R5: 0.0033419262 | S5: 0.00071982622 | T5: 0.00022812296 | U5: 0.0022119728 | V5: 0.0016662933 | W5: 0.0015678061
A6: GLD | B6: 0.2 | C6: =Risk_Analysis!B5 -> 0.12211484 | D6: 0.05 | E6: 0.2 | M6: JPM | N6: -0.00043165769 | O6: 0.0024807543 | P6: 0.0021153543 | Q6: 0.0045851747 | R6: 0.0029717435 | S6: 0.00042739417 | T6: -0.00044737816 | U6: 0.0020819971 | V6: 0.0016028618 | W6: 0.001947222
A7: XOM | B7: 0 | C7: =Risk_Analysis!C5 -> 0.070253093 | D7: 0 | E7: 0.1 | M7: NVDA | N7: -0.00038782129 | O7: 0.0011589623 | P7: 0.0033419262 | Q7: 0.0029717435 | R7: 0.017417735 | S7: 3.4659955e-05 | T7: 0.00073357227 | U7: 0.0053361133 | V7: 0.001955962 | W7: 0.0024888066
A8: SPY | B8: 0.25 | C8: =Risk_Analysis!D5 -> 0.12486957 | D8: 0.25 | E8: 0.4 | M8: PG | N8: 0.00040106929 | O8: 0.00054494567 | P8: 0.00071982622 | Q8: 0.00042739417 | R8: 3.4659955e-05 | S8: 0.0020587096 | T8: 0.00028032469 | U8: 0.00062942519 | V8: 0.0009945604 | W8: 0.00061991401
A9: JPM | B9: 0.15 | C9: =Risk_Analysis!E5 -> 0.18749072 | D9: 0 | E9: 0.15 | M9: TLT | N9: 0.00059542042 | O9: -0.00063112117 | P9: 0.00022812296 | Q9: -0.00044737816 | R9: 0.00073357227 | S9: 0.00028032469 | T9: 0.0014730556 | U9: 0.00043005896 | V9: 0.00080665529 | W9: 0.00025819874
A10: NVDA | B10: 0.15 | C10: =Risk_Analysis!F$5 -> 0.65618323 | D10: 0 | E10: 0.15 | M10: VGT | N10: 4.532527e-05 | O10: 0.0012183664 | P10: 0.0022119728 | Q10: 0.0020819971 | R10: 0.0053361133 | S10: 0.00062942519 | T10: 0.00043005896 | U10: 0.0031707328 | V10: 0.0017301484 | W10: 0.0017455925
A11: PG | B11: 0.1 | C11: =Risk_Analysis!G5 -> 0.064905522 | D11: 0 | E11: 0.1 | M11: VNQ | N11: 0.00033398049 | O11: 0.0014521893 | P11: 0.0016662933 | Q11: 0.0016028618 | R11: 0.001955962 | S11: 0.0009945604 | T11: 0.00080665529 | U11: 0.0017301484 | V11: 0.0025275911 | W11: 0.0014891242
A12: TLT | B12: 0 | C12: =Risk_Analysis!H5 -> -0.032573967 | D12: 0 | E12: 0.2 | M12: VXUS | N12: 0.00041287691 | O12: 0.0015741396 | P12: 0.0015678061 | Q12: 0.001947222 | R12: 0.0024888066 | S12: 0.00061991401 | T12: 0.00025819874 | U12: 0.0017455925 | V12: 0.0014891242 | W12: 0.0018283541
A13: VGT | B13: 0.099999999 | C13: =Risk_Analysis!I5 -> 0.20319714 | D13: 0 | E13: 0.15
A14: VNQ | B14: 0 | C14: =Risk_Analysis!J5 -> 0.019361355 | D14: 0 | E14: 0.15
A15: VXUS | B15: 0.05 | C15: =Risk_Analysis!K5 -> 0.056174267 | D15: 0.05 | E15: 0.2
A26: μ (Train)
A27: Asset | B27: Mean | C27: Weights | D27: MIN | E27: MAX | G27: Variance (Train) | H27: Volatility (Train) | I27: Expected Return (Train) | J27: Sharpe (Train) | K27: sum
A28: GLD | B28: =AVERAGEIFS(Returns!B$3:B$1000, Returns!$A$3:$A$1000, "<="&Out_of_Sample!$C$11) -> 0.0032382798 | C28: 0.2 | D28: 0.05 | E28: 0.2 | G28: {=MMULT(TRANSPOSE($C$28:$C$37),MMULT($B$45:$K$54,$C$28:$C$37))} -> 0.00019476047 | H28: =SQRT(G28) -> 0.013955661 | I28: =SUMPRODUCT($C$28:$C$37,$B$28:$B$37) -> 0.012734211 | J28: =(I28-(H2/12))/H28 -> 0.6736247 | K28: =SUM(C28:C37) -> 1
A29: XOM | B29: =AVERAGEIFS(Returns!C$3:C$1000, Returns!$A$3:$A$1000, "<="&Out_of_Sample!$C$11) -> 0.0031638598 | C29: 0 | D29: 0 | E29: 0.1
A30: SPY | B30: =AVERAGEIFS(Returns!D$3:D$1000, Returns!$A$3:$A$1000, "<="&Out_of_Sample!$C$11) -> 0.0073986602 | C30: 0.25 | D30: 0.25 | E30: 0.4
A31: JPM | B31: =AVERAGEIFS(Returns!E$3:E$1000, Returns!$A$3:$A$1000, "<="&Out_of_Sample!$C$11) -> 0.0095077113 | C31: 0.1 | D31: 0 | E31: 0.15
A32: NVDA | B32: =AVERAGEIFS(Returns!F$3:F$1000, Returns!$A$3:$A$1000, "<="&Out_of_Sample!$C$11) -> 0.044386689 | C32: 0.15 | D32: 0 | E32: 0.15
A33: PG | B33: =AVERAGEIFS(Returns!G$3:G$1000, Returns!$A$3:$A$1000, "<="&Out_of_Sample!$C$11) -> 0.0053666132 | C33: 0.1 | D33: 0 | E33: 0.1
A34: TLT | B34: =AVERAGEIFS(Returns!H$3:H$1000, Returns!$A$3:$A$1000, "<="&Out_of_Sample!$C$11) -> -0.0025943284 | C34: 0 | D34: 0 | E34: 0.2
A35: VGT | B35: =AVERAGEIFS(Returns!I$3:I$1000, Returns!$A$3:$A$1000, "<="&Out_of_Sample!$C$11) -> 0.013824873 | C35: 0.15 | D35: 0 | E35: 0.15
A36: VNQ | B36: =AVERAGEIFS(Returns!J$3:J$1000, Returns!$A$3:$A$1000, "<="&Out_of_Sample!$C$11) -> 0.00048231539 | C36: 0 | D36: 0 | E36: 0.15
A37: VXUS | B37: =AVERAGEIFS(Returns!K$3:K$1000, Returns!$A$3:$A$1000, "<="&Out_of_Sample!$C$11) -> 0.00035447038 | C37: 0.05 | D37: 0.05 | E37: 0.2
A43: Covariance Matrix (Train)
B44: GLD | C44: XOM | D44: SPY | E44: JPM | F44: NVDA | G44: PG | H44: TLT | I44: VGT | J44: VNQ | K44: VXUS
A45: GLD | B45: {=_xlfn.COVARIANCE.P( IF(Returns!$A$3:$A$1000<=Out_of_Sample!$C$11, INDEX(Returns!$B$3:$K$1000,0, MATCH(B$44, Returns!$B$2:$K$2,0))), IF(Returns!$A$3:$A$1000<=Out_of_Sample!$C$11, INDEX(Returns!$B$3:$K$1000,0, MATCH($A45, Returns!$B$2:$K$2,0))) )} -> 0.00015352463 | C45: {=_xlfn.COVARIANCE.P( IF(Returns!$A$3:$A$1000<=Out_of_Sample!$C$11, INDEX(Returns!$B$3:$K$1000,0, MATCH(C$44, Returns!$B$2:$K$2,0))), IF(Returns!$A$3:$A$1000<=Out_of_Sample!$C$11, INDEX(Returns!$B$3:$K$1000,0, MATCH($A45, Returns!$B$2:$K$2,0))) )} -> -2.4770178e-05 | D45: {=_xlfn.COVARIANCE.P( IF(Returns!$A$3:$A$1000<=Out_of_Sample!$C$11, INDEX(Returns!$B$3:$K$1000,0, MATCH(D$44, Returns!$B$2:$K$2,0))), IF(Returns!$A$3:$A$1000<=Out_of_Sample!$C$11, INDEX(Returns!$B$3:$K$1000,0, MATCH($A45, Returns!$B$2:$K$2,0))) )} -> 1.5184674e-05 | E45: {=_xlfn.COVARIANCE.P( IF(Returns!$A$3:$A$1000<=Out_of_Sample!$C$11, INDEX(Returns!$B$3:$K$1000,0, MATCH(E$44, Returns!$B$2:$K$2,0))), IF(Returns!$A$3:$A$1000<=Out_of_Sample!$C$11, INDEX(Returns!$B$3:$K$1000,0, MATCH($A45, Returns!$B$2:$K$2,0))) )} -> -5.1627519e-05 | F45: {=_xlfn.COVARIANCE.P( IF(Returns!$A$3:$A$1000<=Out_of_Sample!$C$11, INDEX(Returns!$B$3:$K$1000,0, MATCH(F$44, Returns!$B$2:$K$2,0))), IF(Returns!$A$3:$A$1000<=Out_of_Sample!$C$11, INDEX(Returns!$B$3:$K$1000,0, MATCH($A45, Returns!$B$2:$K$2,0))) )} -> -2.034726e-05 | G45: {=_xlfn.COVARIANCE.P( IF(Returns!$A$3:$A$1000<=Out_of_Sample!$C$11, INDEX(Returns!$B$3:$K$1000,0, MATCH(G$44, Returns!$B$2:$K$2,0))), IF(Returns!$A$3:$A$1000<=Out_of_Sample!$C$11, INDEX(Returns!$B$3:$K$1000,0, MATCH($A45, Returns!$B$2:$K$2,0))) )} -> 4.8966403e-05 | H45: {=_xlfn.COVARIANCE.P( IF(Returns!$A$3:$A$1000<=Out_of_Sample!$C$11, INDEX(Returns!$B$3:$K$1000,0, MATCH(H$44, Returns!$B$2:$K$2,0))), IF(Returns!$A$3:$A$1000<=Out_of_Sample!$C$11, INDEX(Returns!$B$3:$K$1000,0, MATCH($A45, Returns!$B$2:$K$2,0))) )} -> 5.4520224e-05 | I45: {=_xlfn.COVARIANCE.P( IF(Returns!$A$3:$A$1000<=Out_of_Sample!$C$11, INDEX(Returns!$B$3:$K$1000,0, MATCH(I$44, Returns!$B$2:$K$2,0))), IF(Returns!$A$3:$A$1000<=Out_of_Sample!$C$11, INDEX(Returns!$B$3:$K$1000,0, MATCH($A45, Returns!$B$2:$K$2,0))) )} -> 1.3122402e-05 | ... K45: {=_xlfn.COVARIANCE.P( IF(Returns!$A$3:$A$1000<=Out_of_Sample!$C$11, INDEX(Returns!$B$3:$K$1000,0, MATCH(K$44, Returns!$B$2:$K$2,0))), IF(Returns!$A$3:$A$1000<=Out_of_Sample!$C$11, INDEX(Returns!$B$3:$K$1000,0, MATCH($A45, Returns!$B$2:$K$2,0))) )} -> 2.0607086e-05
A46: XOM | B46: {=_xlfn.COVARIANCE.P( IF(Returns!$A$3:$A$1000<=Out_of_Sample!$C$11, INDEX(Returns!$B$3:$K$1000,0, MATCH(B$44, Returns!$B$2:$K$2,0))), IF(Returns!$A$3:$A$1000<=Out_of_Sample!$C$11, INDEX(Returns!$B$3:$K$1000,0, MATCH($A46, Returns!$B$2:$K$2,0))) )} -> -2.4770178e-05 | C46: {=_xlfn.COVARIANCE.P( IF(Returns!$A$3:$A$1000<=Out_of_Sample!$C$11, INDEX(Returns!$B$3:$K$1000,0, MATCH(C$44, Returns!$B$2:$K$2,0))), IF(Returns!$A$3:$A$1000<=Out_of_Sample!$C$11, INDEX(Returns!$B$3:$K$1000,0, MATCH($A46, Returns!$B$2:$K$2,0))) )} -> 0.00060956078 | D46: {=_xlfn.COVARIANCE.P( IF(Returns!$A$3:$A$1000<=Out_of_Sample!$C$11, INDEX(Returns!$B$3:$K$1000,0, MATCH(D$44, Returns!$B$2:$K$2,0))), IF(Returns!$A$3:$A$1000<=Out_of_Sample!$C$11, INDEX(Returns!$B$3:$K$1000,0, MATCH($A46, Returns!$B$2:$K$2,0))) )} -> 0.00019561779 | E46: {=_xlfn.COVARIANCE.P( IF(Returns!$A$3:$A$1000<=Out_of_Sample!$C$11, INDEX(Returns!$B$3:$K$1000,0, MATCH(E$44, Returns!$B$2:$K$2,0))), IF(Returns!$A$3:$A$1000<=Out_of_Sample!$C$11, INDEX(Returns!$B$3:$K$1000,0, MATCH($A46, Returns!$B$2:$K$2,0))) )} -> 0.00027664457 | F46: {=_xlfn.COVARIANCE.P( IF(Returns!$A$3:$A$1000<=Out_of_Sample!$C$11, INDEX(Returns!$B$3:$K$1000,0, MATCH(F$44, Returns!$B$2:$K$2,0))), IF(Returns!$A$3:$A$1000<=Out_of_Sample!$C$11, INDEX(Returns!$B$3:$K$1000,0, MATCH($A46, Returns!$B$2:$K$2,0))) )} -> 0.00018862721 | G46: {=_xlfn.COVARIANCE.P( IF(Returns!$A$3:$A$1000<=Out_of_Sample!$C$11, INDEX(Returns!$B$3:$K$1000,0, MATCH(G$44, Returns!$B$2:$K$2,0))), IF(Returns!$A$3:$A$1000<=Out_of_Sample!$C$11, INDEX(Returns!$B$3:$K$1000,0, MATCH($A46, Returns!$B$2:$K$2,0))) )} -> 3.45399e-05 | H46: {=_xlfn.COVARIANCE.P( IF(Returns!$A$3:$A$1000<=Out_of_Sample!$C$11, INDEX(Returns!$B$3:$K$1000,0, MATCH(H$44, Returns!$B$2:$K$2,0))), IF(Returns!$A$3:$A$1000<=Out_of_Sample!$C$11, INDEX(Returns!$B$3:$K$1000,0, MATCH($A46, Returns!$B$2:$K$2,0))) )} -> -8.767544e-05 | I46: {=_xlfn.COVARIANCE.P( IF(Returns!$A$3:$A$1000<=Out_of_Sample!$C$11, INDEX(Returns!$B$3:$K$1000,0, MATCH(I$44, Returns!$B$2:$K$2,0))), IF(Returns!$A$3:$A$1000<=Out_of_Sample!$C$11, INDEX(Returns!$B$3:$K$1000,0, MATCH($A46, Returns!$B$2:$K$2,0))) )} -> 0.00017885689 | ... K46: {=_xlfn.COVARIANCE.P( IF(Returns!$A$3:$A$1000<=Out_of_Sample!$C$11, INDEX(Returns!$B$3:$K$1000,0, MATCH(K$44, Returns!$B$2:$K$2,0))), IF(Returns!$A$3:$A$1000<=Out_of_Sample!$C$11, INDEX(Returns!$B$3:$K$1000,0, MATCH($A46, Returns!$B$2:$K$2,0))) )} -> 0.00018833709
A47: SPY | B47: {=_xlfn.COVARIANCE.P( IF(Returns!$A$3:$A$1000<=Out_of_Sample!$C$11, INDEX(Returns!$B$3:$K$1000,0, MATCH(B$44, Returns!$B$2:$K$2,0))), IF(Returns!$A$3:$A$1000<=Out_of_Sample!$C$11, INDEX(Returns!$B$3:$K$1000,0, MATCH($A47, Returns!$B$2:$K$2,0))) )} -> 1.5184674e-05 | C47: {=_xlfn.COVARIANCE.P( IF(Returns!$A$3:$A$1000<=Out_of_Sample!$C$11, INDEX(Returns!$B$3:$K$1000,0, MATCH(C$44, Returns!$B$2:$K$2,0))), IF(Returns!$A$3:$A$1000<=Out_of_Sample!$C$11, INDEX(Returns!$B$3:$K$1000,0, MATCH($A47, Returns!$B$2:$K$2,0))) )} -> 0.00019561779 | D47: {=_xlfn.COVARIANCE.P( IF(Returns!$A$3:$A$1000<=Out_of_Sample!$C$11, INDEX(Returns!$B$3:$K$1000,0, MATCH(D$44, Returns!$B$2:$K$2,0))), IF(Returns!$A$3:$A$1000<=Out_of_Sample!$C$11, INDEX(Returns!$B$3:$K$1000,0, MATCH($A47, Returns!$B$2:$K$2,0))) )} -> 0.00020392375 | E47: {=_xlfn.COVARIANCE.P( IF(Returns!$A$3:$A$1000<=Out_of_Sample!$C$11, INDEX(Returns!$B$3:$K$1000,0, MATCH(E$44, Returns!$B$2:$K$2,0))), IF(Returns!$A$3:$A$1000<=Out_of_Sample!$C$11, INDEX(Returns!$B$3:$K$1000,0, MATCH($A47, Returns!$B$2:$K$2,0))) )} -> 0.00022243061 | F47: {=_xlfn.COVARIANCE.P( IF(Returns!$A$3:$A$1000<=Out_of_Sample!$C$11, INDEX(Returns!$B$3:$K$1000,0, MATCH(F$44, Returns!$B$2:$K$2,0))), IF(Returns!$A$3:$A$1000<=Out_of_Sample!$C$11, INDEX(Returns!$B$3:$K$1000,0, MATCH($A47, Returns!$B$2:$K$2,0))) )} -> 0.00036018944 | G47: {=_xlfn.COVARIANCE.P( IF(Returns!$A$3:$A$1000<=Out_of_Sample!$C$11, INDEX(Returns!$B$3:$K$1000,0, MATCH(G$44, Returns!$B$2:$K$2,0))), IF(Returns!$A$3:$A$1000<=Out_of_Sample!$C$11, INDEX(Returns!$B$3:$K$1000,0, MATCH($A47, Returns!$B$2:$K$2,0))) )} -> 7.6256292e-05 | H47: {=_xlfn.COVARIANCE.P( IF(Returns!$A$3:$A$1000<=Out_of_Sample!$C$11, INDEX(Returns!$B$3:$K$1000,0, MATCH(H$44, Returns!$B$2:$K$2,0))), IF(Returns!$A$3:$A$1000<=Out_of_Sample!$C$11, INDEX(Returns!$B$3:$K$1000,0, MATCH($A47, Returns!$B$2:$K$2,0))) )} -> -6.807137e-06 | I47: {=_xlfn.COVARIANCE.P( IF(Returns!$A$3:$A$1000<=Out_of_Sample!$C$11, INDEX(Returns!$B$3:$K$1000,0, MATCH(I$44, Returns!$B$2:$K$2,0))), IF(Returns!$A$3:$A$1000<=Out_of_Sample!$C$11, INDEX(Returns!$B$3:$K$1000,0, MATCH($A47, Returns!$B$2:$K$2,0))) )} -> 0.00023982609 | ... K47: {=_xlfn.COVARIANCE.P( IF(Returns!$A$3:$A$1000<=Out_of_Sample!$C$11, INDEX(Returns!$B$3:$K$1000,0, MATCH(K$44, Returns!$B$2:$K$2,0))), IF(Returns!$A$3:$A$1000<=Out_of_Sample!$C$11, INDEX(Returns!$B$3:$K$1000,0, MATCH($A47, Returns!$B$2:$K$2,0))) )} -> 0.00017013345
